<mujoco model="rotation">
  <option timestep="0.04" gravity="0 0 0"/>
  <visual><global offwidth="320" offheight="240"/></visual>
  <worldbody>
    <light pos="0 -4 4"/>
    <camera name="track" pos="0 -4 3" xyaxes="1 0 0 0 0.65 0.76"/>
    <body name="rotor" pos="0 0 0.5">
      <joint name="hinge" type="hinge" axis="0 0 1" damping="0.0"/>
      <geom name="bar" type="box" size="0.8 0.06 0.06" mass="1" rgba="0.7 0.35 0.1 1"/>
    </body>
  </worldbody>
  <actuator><motor name="torque" joint="hinge" gear="1"/></actuator>
</mujoco>
